Traceback (most recent call last):
  File "/home/jscheffe/ct-env/lib/python3.12/site-packages/jupyter_cache/executors/utils.py", line 58, in single_nb_execution
    executenb(
  File "/home/jscheffe/ct-env/lib/python3.12/site-packages/nbclient/client.py", line 1319, in execute
    return NotebookClient(nb=nb, resources=resources, km=km, **kwargs).execute()
           ^^^^^^^^^^^^^^^^^^^^^^^^^^^^^^^^^^^^^^^^^^^^^^^^^^^^^^^^^^^^^^^^^^^^^
  File "/home/jscheffe/ct-env/lib/python3.12/site-packages/jupyter_core/utils/__init__.py", line 165, in wrapped
    return loop.run_until_complete(inner)
           ^^^^^^^^^^^^^^^^^^^^^^^^^^^^^^
  File "/usr/lib/python3.12/asyncio/base_events.py", line 687, in run_until_complete
    return future.result()
           ^^^^^^^^^^^^^^^
  File "/home/jscheffe/ct-env/lib/python3.12/site-packages/nbclient/client.py", line 709, in async_execute
    await self.async_execute_cell(
  File "/home/jscheffe/ct-env/lib/python3.12/site-packages/nbclient/client.py", line 1062, in async_execute_cell
    await self._check_raise_for_error(cell, cell_index, exec_reply)
  File "/home/jscheffe/ct-env/lib/python3.12/site-packages/nbclient/client.py", line 918, in _check_raise_for_error
    raise CellExecutionError.from_cell_and_msg(cell, exec_reply_content)
nbclient.exceptions.CellExecutionError: An error occurred while executing the following cell:
------------------
#7.6.3 Exercise 1
#Air enters a 1-m2 pipe at 100 kPa and 20Â°C with a velocity of 180 m/s. Determine the volumetric flow rate, in m3/s, at the inlet and the mass flow rate, in kg/s, at the exit.


A = 1 # m2
Pi = 100 # Pa
Ti = 20 + Kc
vel_i = 180 # m/s
R = 0.287 # kPa*m^3/kgK

# Find: volumetric flow rate at inlet, mass flow rate at exit 
vdot = vel_i*A 

# PV = mRT > P*v = RT > rho = P/RT

rho = Pi/R/Ti

# kg/m^3 * m^3/s = kg/s

mdot_i = rho*vdot
mdot_e = mdot_i
print(f"The volume flow rate at inlet is {round(vdot,1)} m3/s, and the mass flow rate at exit is {round(mdot_e,1)} kg/s")
------------------


[31m---------------------------------------------------------------------------[39m
[31mNameError[39m                                 Traceback (most recent call last)
[36mCell[39m[36m [39m[32mIn[1][39m[32m, line 7[39m
[32m      5[39m A = [32m1[39m [38;5;66;03m# m2[39;00m
[32m      6[39m Pi = [32m100[39m [38;5;66;03m# Pa[39;00m
[32m----> [39m[32m7[39m Ti = [32m20[39m + [43mKc[49m
[32m      8[39m vel_i = [32m180[39m [38;5;66;03m# m/s[39;00m
[32m      9[39m R = [32m0.287[39m [38;5;66;03m# kPa*m^3/kgK[39;00m

[31mNameError[39m: name 'Kc' is not defined

